Workbook

Sheet CAPITAL
A1: CAPITAL | E1: DIVISION | F1: CAPITAL/ TRADE | G1: NEW WEIGHT | H1: WEIGHT = Pers cap/ tot cap
C2: =SUM(C5:D15) -> 3350000
A5: 1 | B5: SA | C5: 150000 | E5: 30 | F5: =C5/E5 -> 5000 | G5: =F5/$F$15 -> 0.052941176 | H5: =C5/$C$2 -> 0.044776119
A6: 2 | B6: SG | C6: 700000 | E6: 35 | F6: =C6/E6 -> 20000 | G6: =F6/$F$15 -> 0.21176471 | H6: =C6/$C$2 -> 0.20895522
A7: 3 | B7: DS | C7: 2500000 | E7: 36 | F7: =C7/E7 -> 69444.444 | G7: =F7/$F$15 -> 0.73529412 | H7: =C7/$C$2 -> 0.74626866
G8: =F8/$F$15 -> 0 | H8: =C8/$C$2 -> 0
G9: =F9/$F$15 -> 0 | H9: =C9/$C$2 -> 0
G10: =F10/$F$15 -> 0 | H10: =C10/$C$2 -> 0
G11: =F11/$F$15 -> 0 | H11: =C11/$C$2 -> 0
G12: =F12/$F$15 -> 0 | H12: =C12/$C$2 -> 0
G13: =F13/$F$15 -> 0 | H13: =C13/$C$2 -> 0
G14: =F14/$F$15 -> 0 | H14: =C14/$C$2 -> 0
A15: =count(A5:A14) -> 3 | F15: =SUM(F5:F14) -> 94444.444 | G15: =SUM(G5:G14) -> 1 | H15: =SUM(H5:H14) -> 1

Sheet ENTRY
A1: Trade No. | B1: Script | C1: Entry Date | D1: Entry Price | E1: Total Qty | F1: Exit Price | G1: Exit Date | H1: SA DIVISION | I1: NK DIVISION | J1: DS DIVISION | K1: SA CAPITAL/ TRADE | L1: NK CAPITAL/ TRADE | M1: DS CAPITAL/ TRADE | N1: TOT CAPITAL/ TRADE | O1: SA WEIGHT | P1: NK WEIGHT | Q1: DS WEIGHT
A3: 1 | B3: EMULTIMQ | C3: 46023 | D3: 41.25 | E3: 2289 | F3: LIVE | H3: 30 | I3: 35 | J3: 36 | K3: =IF(H3=0,0,CAPITAL!$C$5/H3) -> 5000 | L3: =IF(I3=0,0,CAPITAL!$C$6/I3) -> 20000 | M3: =IF(J3=0,0,CAPITAL!$C$7/J3) -> 69444.444 | N3: =K3+L3+M3 -> 94444.444 | O3: =K3/N3 -> 0.052941176 | P3: =L3/N3 -> 0.21176471 | Q3: =M3/N3 -> 0.73529412
A4: 2 | B4: FMCGIETF | C4: 46024 | D4: 56.85 | E4: 1661 | F4: LIVE | H4: 20 | I4: 35 | J4: 36 | K4: =IF(H4=0,0,CAPITAL!$C$5/H4) -> 7500 | L4: =IF(I4=0,0,CAPITAL!$C$6/I4) -> 20000 | M4: =IF(J4=0,0,CAPITAL!$C$7/J4) -> 69444.444 | N4: =K4+L4+M4 -> 96944.444 | O4: =K4/N4 -> 0.077363897 | P4: =L4/N4 -> 0.20630372 | Q4: =M4/N4 -> 0.71633238
A5: 3 | B5: MOHEALTH | C5: 46027 | D5: 44.71 | E5: 2112 | F5: LIVE | H5: 50 | I5: 70 | J5: 40 | K5: =IF(H5=0,0,CAPITAL!$C$5/H5) -> 3000 | L5: =IF(I5=0,0,CAPITAL!$C$6/I5) -> 10000 | M5: =IF(J5=0,0,CAPITAL!$C$7/J5) -> 62500 | N5: =K5+L5+M5 -> 75500 | O5: =K5/N5 -> 0.039735099 | P5: =L5/N5 -> 0.13245033 | Q5: =M5/N5 -> 0.82781457
A6: 4 | B6: MOHEALTH | C6: 46029 | D6: 45.25 | E6: 2087 | F6: LIVE | H6: 30 | I6: 35 | J6: 36 | K6: =IF(H6=0,0,CAPITAL!$C$5/H6) -> 5000 | L6: =IF(I6=0,0,CAPITAL!$C$6/I6) -> 20000 | M6: =IF(J6=0,0,CAPITAL!$C$7/J6) -> 69444.444 | N6: =K6+L6+M6 -> 94444.444 | O6: =K6/N6 -> 0.052941176 | P6: =L6/N6 -> 0.21176471 | Q6: =M6/N6 -> 0.73529412
A7: 5 | B7: SILVERBEES | C7: 46030 | D7: 224.52 | E7: 840 | F7: 239.2 | G7: 46034 | H7: 30 | I7: 35 | J7: 36 | K7: =IF(H7=0,0,CAPITAL!$C$5/H7) -> 5000 | L7: =IF(I7=0,0,CAPITAL!$C$6/I7) -> 20000 | M7: =IF(J7=0,0,CAPITAL!$C$7/J7) -> 69444.444 | N7: =K7+L7+M7 -> 94444.444 | O7: =K7/N7 -> 0.052941176 | P7: =L7/N7 -> 0.21176471 | Q7: =M7/N7 -> 0.73529412
A8: 6 | B8: HNGSNGBEES | C8: 46031 | D8: 501.25 | E8: 180 | F8: 517.3 | G8: 46034 | H8: 0 | I8: 0 | J8: 36 | K8: =IF(H8=0,0,CAPITAL!$C$5/H8) -> 0 | L8: =IF(I8=0,0,CAPITAL!$C$6/I8) -> 0 | M8: =IF(J8=0,0,CAPITAL!$C$7/J8) -> 69444.444 | N8: =K8+L8+M8 -> 69444.444 | O8: =K8/N8 -> 0 | P8: =L8/N8 -> 0 | Q8: =M8/N8 -> 1
A9: 7 | B9: SILVERBEES | C9: 46036 | D9: 260.15 | E9: 269 | F9: 280.95 | G9: 46041 | H9: 0 | I9: 0 | J9: 36 | K9: =IF(H9=0,0,CAPITAL!$C$5/H9) -> 0 | L9: =IF(I9=0,0,CAPITAL!$C$6/I9) -> 0 | M9: =IF(J9=0,0,CAPITAL!$C$7/J9) -> 69444.444 | N9: =K9+L9+M9 -> 69444.444 | O9: =K9/N9 -> 0 | P9: =L9/N9 -> 0 | Q9: =M9/N9 -> 1
A10: 8 | B10: GOLDBEES | C10: 46038 | D10: 117.5 | E10: 595 | F10: 122.63 | G10: 46042 | H10: 0 | I10: 0 | J10: 36 | K10: =IF(H10=0,0,CAPITAL!$C$5/H10) -> 0 | L10: =IF(I10=0,0,CAPITAL!$C$6/I10) -> 0 | M10: =IF(J10=0,0,CAPITAL!$C$7/J10) -> 69444.444 | N10: =K10+L10+M10 -> 69444.444 | O10: =K10/N10 -> 0 | P10: =L10/N10 -> 0 | Q10: =M10/N10 -> 1
A11: 9 | B11: SILVERBEES | C11: 46038 | D11: 269.3 | E11: 259 | F11: 280.95 | G11: 46041 | H11: 0 | I11: 0 | J11: 36 | K11: =IF(H11=0,0,CAPITAL!$C$5/H11) -> 0 | L11: =IF(I11=0,0,CAPITAL!$C$6/I11) -> 0 | M11: =IF(J11=0,0,CAPITAL!$C$7/J11) -> 69444.444 | N11: =K11+L11+M11 -> 69444.444 | O11: =K11/N11 -> 0 | P11: =L11/N11 -> 0 | Q11: =M11/N11 -> 1
A12: 10 | B12: SILVER LIFE (ADITYA BIRLA) | C12: 46041 | D12: 292.94 | E12: 238 | F12: 311.85 | G12: 46042 | H12: 0 | I12: 0 | J12: 36 | K12: =IF(H12=0,0,CAPITAL!$C$5/H12) -> 0 | L12: =IF(I12=0,0,CAPITAL!$C$6/I12) -> 0 | M12: =IF(J12=0,0,CAPITAL!$C$7/J12) -> 69444.444 | N12: =K12+L12+M12 -> 69444.444 | O12: =K12/N12 -> 0 | P12: =L12/N12 -> 0 | Q12: =M12/N12 -> 1
A13: 11 | B13: TWCGOLD TEF | C13: 46042 | D13: 148.5 | E13: 473 | F13: 158.07 | G13: 46043 | H13: 0 | I13: 0 | J13: 36 | K13: =IF(H13=0,0,CAPITAL!$C$5/H13) -> 0 | L13: =IF(I13=0,0,CAPITAL!$C$6/I13) -> 0 | M13: =IF(J13=0,0,CAPITAL!$C$7/J13) -> 69444.444 | N13: =K13+L13+M13 -> 69444.444 | O13: =K13/N13 -> 0 | P13: =L13/N13 -> 0 | Q13: =M13/N13 -> 1
A14: 12 | B14: SILVERBAND (BANDHAN BANK) | C14: 46042 | D14: 326.44 | E14: 522 | F14: LIVE | H14: 0 | I14: 0 | J14: 36 | K14: =IF(H14=0,0,CAPITAL!$C$5/H14) -> 0 | L14: =IF(I14=0,0,CAPITAL!$C$6/I14) -> 0 | M14: =IF(J14=0,0,CAPITAL!$C$7/J14) -> 69444.444 | N14: =K14+L14+M14 -> 69444.444 | O14: =K14/N14 -> 0 | P14: =L14/N14 -> 0 | Q14: =M14/N14 -> 1
A15: 13 | B15: SILVERBEES | C15: 46043 | D15: 304.57 | E15: 473 | F15: 315.56 | G15: 46049 | H15: 0 | I15: 0 | J15: 36 | K15: =IF(H15=0,0,CAPITAL!$C$5/H15) -> 0 | L15: =IF(I15=0,0,CAPITAL!$C$6/I15) -> 0 | M15: =IF(J15=0,0,CAPITAL!$C$7/J15) -> 69444.444 | N15: =K15+L15+M15 -> 69444.444 | O15: =K15/N15 -> 0 | P15: =L15/N15 -> 0 | Q15: =M15/N15 -> 1
A16: 14 | B16: SILVERBAND (BANDHAN BANK) | C16: 46044 | D16: 295.2 | E16: 237 | F16: LIVE | H16: 0 | I16: 0 | J16: 36 | K16: =IF(H16=0,0,CAPITAL!$C$5/H16) -> 0 | L16: =IF(I16=0,0,CAPITAL!$C$6/I16) -> 0 | M16: =IF(J16=0,0,CAPITAL!$C$7/J16) -> 69444.444 | N16: =K16+L16+M16 -> 69444.444 | O16: =K16/N16 -> 0 | P16: =L16/N16 -> 0 | Q16: =M16/N16 -> 1
A17: 15 | B17: SILVERBEES | C17: 46044 | D17: 271.82 | E17: 257 | F17: 315.56 | G17: 46049 | H17: 0 | I17: 0 | J17: 36 | K17: =IF(H17=0,0,CAPITAL!$C$5/H17) -> 0 | L17: =IF(I17=0,0,CAPITAL!$C$6/I17) -> 0 | M17: =IF(J17=0,0,CAPITAL!$C$7/J17) -> 69444.444 | N17: =K17+L17+M17 -> 69444.444 | O17: =K17/N17 -> 0 | P17: =L17/N17 -> 0 | Q17: =M17/N17 -> 1
A18: 16 | B18: SILVERBEES | H18: 0 | I18: 0 | J18: 36 | K18: =IF(H18=0,0,CAPITAL!$C$5/H18) -> 0 | L18: =IF(I18=0,0,CAPITAL!$C$6/I18) -> 0 | M18: =IF(J18=0,0,CAPITAL!$C$7/J18) -> 69444.444 | N18: =K18+L18+M18 -> 69444.444 | O18: =K18/N18 -> 0 | P18: =L18/N18 -> 0 | Q18: =M18/N18 -> 1
A19: 17 | B19: SILVERBEES | H19: 0 | I19: 0 | J19: 36 | K19: =IF(H19=0,0,CAPITAL!$C$5/H19) -> 0 | L19: =IF(I19=0,0,CAPITAL!$C$6/I19) -> 0 | M19: =IF(J19=0,0,CAPITAL!$C$7/J19) -> 69444.444 | N19: =K19+L19+M19 -> 69444.444 | O19: =K19/N19 -> 0 | P19: =L19/N19 -> 0 | Q19: =M19/N19 -> 1
A20: 18 | B20: SILVERBEES | H20: 0 | I20: 35 | J20: 36 | K20: =IF(H20=0,0,CAPITAL!$C$5/H20) -> 0 | L20: =IF(I20=0,0,CAPITAL!$C$6/I20) -> 20000 | M20: =IF(J20=0,0,CAPITAL!$C$7/J20) -> 69444.444 | N20: =K20+L20+M20 -> 89444.444 | O20: =K20/N20 -> 0 | P20: =L20/N20 -> 0.22360248 | Q20: =M20/N20 -> 0.77639752
A21: 19 | B21: SILVERBEES | H21: 30 | I21: 35 | J21: 36 | K21: =IF(H21=0,0,CAPITAL!$C$5/H21) -> 5000 | L21: =IF(I21=0,0,CAPITAL!$C$6/I21) -> 20000 | M21: =IF(J21=0,0,CAPITAL!$C$7/J21) -> 69444.444 | N21: =K21+L21+M21 -> 94444.444 | O21: =K21/N21 -> 0.052941176 | P21: =L21/N21 -> 0.21176471 | Q21: =M21/N21 -> 0.73529412
A22: 20 | B22: SILVERBEES | H22: 30 | I22: 35 | J22: 36 | K22: =IF(H22=0,0,CAPITAL!$C$5/H22) -> 5000 | L22: =IF(I22=0,0,CAPITAL!$C$6/I22) -> 20000 | M22: =IF(J22=0,0,CAPITAL!$C$7/J22) -> 69444.444 | N22: =K22+L22+M22 -> 94444.444 | O22: =K22/N22 -> 0.052941176 | P22: =L22/N22 -> 0.21176471 | Q22: =M22/N22 -> 0.73529412
A23: 21 | B23: SILVERBEES | H23: 30 | I23: 35 | J23: 36 | K23: =IF(H23=0,0,CAPITAL!$C$5/H23) -> 5000 | L23: =IF(I23=0,0,CAPITAL!$C$6/I23) -> 20000 | M23: =IF(J23=0,0,CAPITAL!$C$7/J23) -> 69444.444 | N23: =K23+L23+M23 -> 94444.444 | O23: =K23/N23 -> 0.052941176 | P23: =L23/N23 -> 0.21176471 | Q23: =M23/N23 -> 0.73529412
A24: 22 | B24: SILVERBEES | H24: 30 | I24: 35 | J24: 36 | K24: =IF(H24=0,0,CAPITAL!$C$5/H24) -> 5000 | L24: =IF(I24=0,0,CAPITAL!$C$6/I24) -> 20000 | M24: =IF(J24=0,0,CAPITAL!$C$7/J24) -> 69444.444 | N24: =K24+L24+M24 -> 94444.444 | O24: =K24/N24 -> 0.052941176 | P24: =L24/N24 -> 0.21176471 | Q24: =M24/N24 -> 0.73529412
A25: 23 | B25: SILVERBEES | H25: 30 | I25: 35 | J25: 36 | K25: =IF(H25=0,0,CAPITAL!$C$5/H25) -> 5000 | L25: =IF(I25=0,0,CAPITAL!$C$6/I25) -> 20000 | M25: =IF(J25=0,0,CAPITAL!$C$7/J25) -> 69444.444 | N25: =K25+L25+M25 -> 94444.444 | O25: =K25/N25 -> 0.052941176 | P25: =L25/N25 -> 0.21176471 | Q25: =M25/N25 -> 0.73529412
A26: 24 | B26: SILVERBEES | H26: 30 | I26: 35 | J26: 36 | K26: =IF(H26=0,0,CAPITAL!$C$5/H26) -> 5000 | L26: =IF(I26=0,0,CAPITAL!$C$6/I26) -> 20000 | M26: =IF(J26=0,0,CAPITAL!$C$7/J26) -> 69444.444 | N26: =K26+L26+M26 -> 94444.444 | O26: =K26/N26 -> 0.052941176 | P26: =L26/N26 -> 0.21176471 | Q26: =M26/N26 -> 0.73529412
A27: 25 | B27: SILVERBEES | H27: 30 | I27: 35 | J27: 36 | K27: =IF(H27=0,0,CAPITAL!$C$5/H27) -> 5000 | L27: =IF(I27=0,0,CAPITAL!$C$6/I27) -> 20000 | M27: =IF(J27=0,0,CAPITAL!$C$7/J27) -> 69444.444 | N27: =K27+L27+M27 -> 94444.444 | O27: =K27/N27 -> 0.052941176 | P27: =L27/N27 -> 0.21176471 | Q27: =M27/N27 -> 0.73529412
A28: 26 | B28: SILVERBEES | H28: 30 | I28: 35 | J28: 36 | K28: =IF(H28=0,0,CAPITAL!$C$5/H28) -> 5000 | L28: =IF(I28=0,0,CAPITAL!$C$6/I28) -> 20000 | M28: =IF(J28=0,0,CAPITAL!$C$7/J28) -> 69444.444 | N28: =K28+L28+M28 -> 94444.444 | O28: =K28/N28 -> 0.052941176 | P28: =L28/N28 -> 0.21176471 | Q28: =M28/N28 -> 0.73529412
A29: 27 | B29: SILVERBEES | H29: 30 | I29: 35 | J29: 36 | K29: =IF(H29=0,0,CAPITAL!$C$5/H29) -> 5000 | L29: =IF(I29=0,0,CAPITAL!$C$6/I29) -> 20000 | M29: =IF(J29=0,0,CAPITAL!$C$7/J29) -> 69444.444 | N29: =K29+L29+M29 -> 94444.444 | O29: =K29/N29 -> 0.052941176 | P29: =L29/N29 -> 0.21176471 | Q29: =M29/N29 -> 0.73529412
... A494: 492 | B494: SILVERBEES | H494: 30 | I494: 35 | J494: 36 | K494: =IF(H494=0,0,CAPITAL!$C$5/H494) -> 5000 | L494: =IF(I494=0,0,CAPITAL!$C$6/I494) -> 20000 | M494: =IF(J494=0,0,CAPITAL!$C$7/J494) -> 69444.444 | N494: =K494+L494+M494 -> 94444.444 | O494: =K494/N494 -> 0.052941176 | P494: =L494/N494 -> 0.21176471 | Q494: =M494/N494 -> 0.73529412
A495: 493 | H495: 30 | I495: 35 | J495: 36 | K495: =IF(H495=0,0,CAPITAL!$C$5/H495) -> 5000 | L495: =IF(I495=0,0,CAPITAL!$C$6/I495) -> 20000 | M495: =IF(J495=0,0,CAPITAL!$C$7/J495) -> 69444.444 | N495: =K495+L495+M495 -> 94444.444 | O495: =K495/N495 -> 0.052941176 | P495: =L495/N495 -> 0.21176471 | Q495: =M495/N495 -> 0.73529412
A496: 494 | H496: 30 | I496: 35 | J496: 36 | K496: =IF(H496=0,0,CAPITAL!$C$5/H496) -> 5000 | L496: =IF(I496=0,0,CAPITAL!$C$6/I496) -> 20000 | M496: =IF(J496=0,0,CAPITAL!$C$7/J496) -> 69444.444 | N496: =K496+L496+M496 -> 94444.444 | O496: =K496/N496 -> 0.052941176 | P496: =L496/N496 -> 0.21176471 | Q496: =M496/N496 -> 0.73529412
A497: 495 | H497: 30 | I497: 35 | J497: 36 | K497: =IF(H497=0,0,CAPITAL!$C$5/H497) -> 5000 | L497: =IF(I497=0,0,CAPITAL!$C$6/I497) -> 20000 | M497: =IF(J497=0,0,CAPITAL!$C$7/J497) -> 69444.444 | N497: =K497+L497+M497 -> 94444.444 | O497: =K497/N497 -> 0.052941176 | P497: =L497/N497 -> 0.21176471 | Q497: =M497/N497 -> 0.73529412
A498: 496 | H498: 30 | I498: 35 | J498: 36 | K498: =IF(H498=0,0,CAPITAL!$C$5/H498) -> 5000 | L498: =IF(I498=0,0,CAPITAL!$C$6/I498) -> 20000 | M498: =IF(J498=0,0,CAPITAL!$C$7/J498) -> 69444.444 | N498: =K498+L498+M498 -> 94444.444 | O498: =K498/N498 -> 0.052941176 | P498: =L498/N498 -> 0.21176471 | Q498: =M498/N498 -> 0.73529412
A499: 497 | H499: 30 | I499: 35 | J499: 36 | K499: =IF(H499=0,0,CAPITAL!$C$5/H499) -> 5000 | L499: =IF(I499=0,0,CAPITAL!$C$6/I499) -> 20000 | M499: =IF(J499=0,0,CAPITAL!$C$7/J499) -> 69444.444 | N499: =K499+L499+M499 -> 94444.444 | O499: =K499/N499 -> 0.052941176 | P499: =L499/N499 -> 0.21176471 | Q499: =M499/N499 -> 0.73529412
A500: 498 | H500: 30 | I500: 35 | J500: 36 | K500: =IF(H500=0,0,CAPITAL!$C$5/H500) -> 5000 | L500: =IF(I500=0,0,CAPITAL!$C$6/I500) -> 20000 | M500: =IF(J500=0,0,CAPITAL!$C$7/J500) -> 69444.444 | N500: =K500+L500+M500 -> 94444.444 | O500: =K500/N500 -> 0.052941176 | P500: =L500/N500 -> 0.21176471 | Q500: =M500/N500 -> 0.73529412
A501: 499 | H501: 30 | I501: 35 | J501: 36 | K501: =IF(H501=0,0,CAPITAL!$C$5/H501) -> 5000 | L501: =IF(I501=0,0,CAPITAL!$C$6/I501) -> 20000 | M501: =IF(J501=0,0,CAPITAL!$C$7/J501) -> 69444.444 | N501: =K501+L501+M501 -> 94444.444 | O501: =K501/N501 -> 0.052941176 | P501: =L501/N501 -> 0.21176471 | Q501: =M501/N501 -> 0.73529412
A502: 500 | H502: 30 | I502: 35 | J502: 36 | K502: =IF(H502=0,0,CAPITAL!$C$5/H502) -> 5000 | L502: =IF(I502=0,0,CAPITAL!$C$6/I502) -> 20000 | M502: =IF(J502=0,0,CAPITAL!$C$7/J502) -> 69444.444 | N502: =K502+L502+M502 -> 94444.444 | O502: =K502/N502 -> 0.052941176 | P502: =L502/N502 -> 0.21176471 | Q502: =M502/N502 -> 0.73529412
H503: 30 | I503: 35 | J503: 36 | K503: =IF(H503=0,0,CAPITAL!$C$5/H503) -> 5000 | L503: =IF(I503=0,0,CAPITAL!$C$6/I503) -> 20000 | M503: =IF(J503=0,0,CAPITAL!$C$7/J503) -> 69444.444 | N503: =K503+L503+M503 -> 94444.444 | O503: =K503/N503 -> 0.052941176 | P503: =L503/N503 -> 0.21176471 | Q503: =M503/N503 -> 0.73529412
H504: 30 | I504: 35 | J504: 36 | K504: =IF(H504=0,0,CAPITAL!$C$5/H504) -> 5000 | L504: =IF(I504=0,0,CAPITAL!$C$6/I504) -> 20000 | M504: =IF(J504=0,0,CAPITAL!$C$7/J504) -> 69444.444 | N504: =K504+L504+M504 -> 94444.444 | O504: =K504/N504 -> 0.052941176 | P504: =L504/N504 -> 0.21176471 | Q504: =M504/N504 -> 0.73529412
H505: 30 | I505: 35 | J505: 36 | K505: =IF(H505=0,0,CAPITAL!$C$5/H505) -> 5000 | L505: =IF(I505=0,0,CAPITAL!$C$6/I505) -> 20000 | M505: =IF(J505=0,0,CAPITAL!$C$7/J505) -> 69444.444 | N505: =K505+L505+M505 -> 94444.444 | O505: =K505/N505 -> 0.052941176 | P505: =L505/N505 -> 0.21176471 | Q505: =M505/N505 -> 0.73529412
...

Sheet JOURNAL
B1: m
M2: 2026
C3: Total Gain on Capital → | K3: =IFERROR(__xludf.DUMMYFUNCTION("SUM( FILTER(X9:X1015, ISNUMBER(X9:X1015)) )"),0.015051871641791037) -> 0.015051872 | L3: =IFERROR(__xludf.DUMMYFUNCTION("SUM( FILTER(S9:S1015, ISNUMBER(S9:S1015)) )"),50423.769999999975) -> 50423.77
U5: TOTAL CAPITAL | X5: =CAPITAL!C2 -> 3350000
B6: Trade No. | C6: Script | D6: Capital | E6: Entry Date | F6: Entry Price | G6: Total Qty | H6: SA - Qty | I6: SG - Qty | J6: DS - Qty | K6: Investment | L6: Exit Price | M6: Exit Date | N6: ROI | T6: =IFERROR(__xludf.DUMMYFUNCTION("SUM( FILTER(T9:T1015, ISNUMBER(T9:T1015)) )"),633.4594293239675) -> 633.45943 | U6: =IFERROR(__xludf.DUMMYFUNCTION("SUM( FILTER(U9:U1015, ISNUMBER(U9:U1015)) )"),2520.9251799824374) -> 2520.9252 | V6: =IFERROR(__xludf.DUMMYFUNCTION("SUM( FILTER(V9:V1015, ISNUMBER(V9:V1015)) )"),47648.81524143984) -> 47648.815 | X6: ROC | Y6: Brokerage | Z6: Brokerage - SA | AA6: Brokerage - SG | AB6: Brokerage - DS
N7: % | O7: Profit | P7: SA Profit | Q7: SG Profit | R7: DS Profit | S7: Net Profit | T7: SA Net Profit | U7: SG Net Profit | V7: DS Net Profit | W7: Net % | X7: %
A9: MOM30IETF | B9: 1 | C9: =ENTRY!B3 -> EMULTIMQ | D9: =CAPITAL!$C$2 -> 3350000 | E9: =ENTRY!C3 -> 46023 | F9: =ENTRY!D3 -> 41.25 | G9: =ENTRY!E3 -> 2289 | H9: =G9*ENTRY!$O3 -> 121.18235 | I9: =G9*ENTRY!$P3 -> 484.72941 | J9: =G9*ENTRY!$Q3 -> 1683.0882 | K9: =F9*G9 -> 94421.25 | L9: =ENTRY!F3 -> LIVE | M9: =ENTRY!G3 | N9: =IFERROR(((L9-F9)*G9)/K9,"") | O9: =IFERROR(N9*K9,"") -> 0 | P9: =IFERROR((F9*H9)*N9,"") -> 0 | Q9: =IFERROR((F9*I9)*N9,"") -> 0 | R9: =IFERROR((F9*J9)*N9,"") -> 0 | S9: =IFERROR(O9-Y9,"") | T9: =IFERROR(P9-Z9,"") | U9: =IFERROR(Q9-AA9,"") | V9: =IFERROR(R9-AB9,"") | W9: =IFERROR(S9/K9,"") -> 0 | X9: =IFERROR(S9/D9,"") -> 0 | Y9: =Brokerage(F9, L9, G9) -> ERR | Z9: =IF(H9=0,0,CAPITAL!$H$5*Y9) -> #VALUE! | AA9: =IF(I9=0,0,CAPITAL!$H$6*Y9) -> #VALUE! | AB9: =IF(J9=0,0,CAPITAL!$H$7*Y9) -> #VALUE!
A10: NIFTYQLITY | B10: 2 | C10: =ENTRY!B4 -> FMCGIETF | D10: =CAPITAL!$C$2 -> 3350000 | E10: =ENTRY!C4 -> 46024 | F10: =ENTRY!D4 -> 56.85 | G10: =ENTRY!E4 -> 1661 | H10: =G10*ENTRY!$O4 -> 128.50143 | I10: =G10*ENTRY!$P4 -> 342.67049 | J10: =G10*ENTRY!$Q4 -> 1189.8281 | K10: =F10*G10 -> 94427.85 | L10: =ENTRY!F4 -> LIVE | M10: =ENTRY!G4 | N10: =IFERROR(((L10-F10)*G10)/K10,"") | O10: =IFERROR(N10*K10,"") -> 0 | P10: =IFERROR((F10*H10)*N10,"") -> 0 | Q10: =IFERROR((F10*I10)*N10,"") -> 0 | R10: =IFERROR((F10*J10)*N10,"") -> 0 | S10: =IFERROR(O10-Y10,"") | T10: =IFERROR(P10-Z10,"") | U10: =IFERROR(Q10-AA10,"") | V10: =IFERROR(R10-AB10,"") | W10: =IFERROR(S10/K10,"") -> 0 | X10: =S10/D10 -> 0 | Y10: =Brokerage(F10, L10, G10) -> ERR | Z10: =IF(H10=0,0,CAPITAL!$H$5*Y10) -> #VALUE! | AA10: =IF(I10=0,0,CAPITAL!$H$6*Y10) -> #VALUE! | AB10: =IF(J10=0,0,CAPITAL!$H$7*Y10) -> #VALUE!
A11: VAL30IETF | B11: 3 | C11: =ENTRY!B5 -> MOHEALTH | D11: =CAPITAL!$C$2 -> 3350000 | E11: =ENTRY!C5 -> 46027 | F11: =ENTRY!D5 -> 44.71 | G11: =ENTRY!E5 -> 2112 | H11: =G11*ENTRY!$O5 -> 83.92053 | I11: =G11*ENTRY!$P5 -> 279.7351 | J11: =G11*ENTRY!$Q5 -> 1748.3444 | K11: =F11*G11 -> 94427.52 | L11: =ENTRY!F5 -> LIVE | M11: =ENTRY!G5 | N11: =IFERROR(((L11-F11)*G11)/K11,"") | O11: =IFERROR(N11*K11,"") -> 0 | P11: =IFERROR((F11*H11)*N11,"") -> 0 | Q11: =IFERROR((F11*I11)*N11,"") -> 0 | R11: =IFERROR((F11*J11)*N11,"") -> 0 | S11: =IFERROR(O11-Y11,"") | T11: =IFERROR(P11-Z11,"") | U11: =IFERROR(Q11-AA11,"") | V11: =IFERROR(R11-AB11,"") | W11: =IFERROR(S11/K11,"") -> 0 | X11: =IFERROR(S11/D11,"") -> 0 | Y11: =Brokerage(F11, L11, G11) -> ERR | Z11: =IF(H11=0,0,CAPITAL!$H$5*Y11) -> #VALUE! | AA11: =IF(I11=0,0,CAPITAL!$H$6*Y11) -> #VALUE! | AB11: =IF(J11=0,0,CAPITAL!$H$7*Y11) -> #VALUE!
A12: ABSLPSE | B12: 4 | C12: =ENTRY!B6 -> MOHEALTH | D12: =CAPITAL!$C$2 -> 3350000 | E12: =ENTRY!C6 -> 46029 | F12: =ENTRY!D6 -> 45.25 | G12: =ENTRY!E6 -> 2087 | H12: =G12*ENTRY!$O6 -> 110.48824 | I12: =G12*ENTRY!$P6 -> 441.95294 | J12: =G12*ENTRY!$Q6 -> 1534.5588 | K12: =F12*G12 -> 94436.75 | L12: =ENTRY!F6 -> LIVE | M12: =ENTRY!G6 | N12: =IFERROR(((L12-F12)*G12)/K12,"") | O12: =IFERROR(N12*K12,"") -> 0 | P12: =IFERROR((F12*H12)*N12,"") -> 0 | Q12: =IFERROR((F12*I12)*N12,"") -> 0 | R12: =IFERROR((F12*J12)*N12,"") -> 0 | S12: =IFERROR(O12-Y12,"") | T12: =IFERROR(P12-Z12,"") | U12: =IFERROR(Q12-AA12,"") | V12: =IFERROR(R12-AB12,"") | W12: =IFERROR(S12/K12,"") -> 0 | X12: =S12/D12 -> 0 | Y12: =Brokerage(F12, L12, G12) -> ERR | Z12: =IF(H12=0,0,CAPITAL!$H$5*Y12) -> #VALUE! | AA12: =IF(I12=0,0,CAPITAL!$H$6*Y12) -> #VALUE! | AB12: =IF(J12=0,0,CAPITAL!$H$7*Y12) -> #VALUE!
A13: UTISXN50 | B13: 5 | C13: =ENTRY!B7 -> SILVERBEES | D13: =CAPITAL!$C$2 -> 3350000 | E13: =ENTRY!C7 -> 46030 | F13: =ENTRY!D7 -> 224.52 | G13: =ENTRY!E7 -> 840 | H13: =G13*ENTRY!$O7 -> 44.470588 | I13: =G13*ENTRY!$P7 -> 177.88235 | J13: =G13*ENTRY!$Q7 -> 617.64706 | K13: =F13*G13 -> 188596.8 | L13: =ENTRY!F7 -> 239.2 | M13: =ENTRY!G7 -> 46034 | N13: =IFERROR(((L13-F13)*G13)/K13,"") -> 0.06538393 | O13: =IFERROR(N13*K13,"") -> 12331.2 | P13: =IFERROR((F13*H13)*N13,"") -> 652.82824 | Q13: =IFERROR((F13*I13)*N13,"") -> 2611.3129 | R13: =IFERROR((F13*J13)*N13,"") -> 9067.0588 | S13: =IFERROR(O13-Y13,"") -> 11898.63 | T13: =IFERROR(P13-Z13,"") -> 633.45943 | U13: =IFERROR(Q13-AA13,"") -> 2520.9252 | V13: =IFERROR(R13-AB13,"") -> 8744.2454 | W13: =IFERROR(S13/K13,"") -> 0.063090307 | X13: =IFERROR(S13/D13,"") -> 0.0035518299 | Y13: =Brokerage(F13, L13, G13) -> 432.57 | Z13: =IF(H13=0,0,CAPITAL!$H$5*Y13) -> 19.368806 | AA13: =IF(I13=0,0,CAPITAL!$H$6*Y13) -> 90.387761 | AB13: =IF(J13=0,0,CAPITAL!$H$7*Y13) -> 322.81343
A14: CPSEETF | B14: 6 | C14: =ENTRY!B8 -> HNGSNGBEES | D14: =CAPITAL!$C$2 -> 3350000 | E14: =ENTRY!C8 -> 46031 | F14: =ENTRY!D8 -> 501.25 | G14: =ENTRY!E8 -> 180 | H14: =G14*ENTRY!$O8 -> 0 | I14: =G14*ENTRY!$P8 -> 0 | J14: =G14*ENTRY!$Q8 -> 180 | K14: =F14*G14 -> 90225 | L14: =ENTRY!F8 -> 517.3 | M14: =ENTRY!G8 -> 46034 | N14: =IFERROR(((L14-F14)*G14)/K14,"") -> 0.03201995 | O14: =IFERROR(N14*K14,"") -> 2889 | P14: =IFERROR((F14*H14)*N14,"") -> 0 | Q14: =IFERROR((F14*I14)*N14,"") -> 0 | R14: =IFERROR((F14*J14)*N14,"") -> 2889 | S14: =IFERROR(O14-Y14,"") -> 2685.14 | T14: =IFERROR(P14-Z14,"") -> 0 | U14: =IFERROR(Q14-AA14,"") -> 0 | V14: =IFERROR(R14-AB14,"") -> 2736.8657 | W14: =IFERROR(S14/K14,"") -> 0.029760488 | X14: =S14/D14 -> 0.00080153433 | Y14: =Brokerage(F14, L14, G14) -> 203.86 | Z14: =IF(H14=0,0,CAPITAL!$H$5*Y14) -> 0 | AA14: =IF(I14=0,0,CAPITAL!$H$6*Y14) -> 0 | AB14: =IF(J14=0,0,CAPITAL!$H$7*Y14) -> 152.13433
A15: GOLDBEES | B15: 7 | C15: =ENTRY!B9 -> SILVERBEES | D15: =CAPITAL!$C$2 -> 3350000 | E15: =ENTRY!C9 -> 46036 | F15: =ENTRY!D9 -> 260.15 | G15: =ENTRY!E9 -> 269 | H15: =G15*ENTRY!$O9 -> 0 | I15: =G15*ENTRY!$P9 -> 0 | J15: =G15*ENTRY!$Q9 -> 269 | K15: =F15*G15 -> 69980.35 | L15: =ENTRY!F9 -> 280.95 | M15: =ENTRY!G9 -> 46041 | N15: =IFERROR(((L15-F15)*G15)/K15,"") -> 0.079953873 | O15: =IFERROR(N15*K15,"") -> 5595.2 | P15: =IFERROR((F15*H15)*N15,"") -> 0 | Q15: =IFERROR((F15*I15)*N15,"") -> 0 | R15: =IFERROR((F15*J15)*N15,"") -> 5595.2 | S15: =IFERROR(O15-Y15,"") -> 5433.75 | T15: =IFERROR(P15-Z15,"") -> 0 | U15: =IFERROR(Q15-AA15,"") -> 0 | V15: =IFERROR(R15-AB15,"") -> 5474.7149 | W15: =IFERROR(S15/K15,"") -> 0.077646797 | X15: =IFERROR(S15/D15,"") -> 0.0016220149 | Y15: =Brokerage(F15, L15, G15) -> 161.45 | Z15: =IF(H15=0,0,CAPITAL!$H$5*Y15) -> 0 | AA15: =IF(I15=0,0,CAPITAL!$H$6*Y15) -> 0 | AB15: =IF(J15=0,0,CAPITAL!$H$7*Y15) -> 120.48507
A16: HNGSNGBEES | B16: 8 | C16: =ENTRY!B10 -> GOLDBEES | D16: =CAPITAL!$C$2 -> 3350000 | E16: =ENTRY!C10 -> 46038 | F16: =ENTRY!D10 -> 117.5 | G16: =ENTRY!E10 -> 595 | H16: =G16*ENTRY!$O10 -> 0 | I16: =G16*ENTRY!$P10 -> 0 | J16: =G16*ENTRY!$Q10 -> 595 | K16: =F16*G16 -> 69912.5 | L16: =ENTRY!F10 -> 122.63 | M16: =ENTRY!G10 -> 46042 | N16: =IFERROR(((L16-F16)*G16)/K16,"") -> 0.043659574 | O16: =IFERROR(N16*K16,"") -> 3052.35 | P16: =IFERROR((F16*H16)*N16,"") -> 0 | Q16: =IFERROR((F16*I16)*N16,"") -> 0 | R16: =IFERROR((F16*J16)*N16,"") -> 3052.35 | S16: =IFERROR(O16-Y16,"") -> 2894 | T16: =IFERROR(P16-Z16,"") -> 0 | U16: =IFERROR(Q16-AA16,"") -> 0 | V16: =IFERROR(R16-AB16,"") -> 2934.1784 | W16: =IFERROR(S16/K16,"") -> 0.0413946 | X16: =S16/D16 -> 0.0008638806 | Y16: =Brokerage(F16, L16, G16) -> 158.35 | Z16: =IF(H16=0,0,CAPITAL!$H$5*Y16) -> 0 | AA16: =IF(I16=0,0,CAPITAL!$H$6*Y16) -> 0 | AB16: =IF(J16=0,0,CAPITAL!$H$7*Y16) -> 118.17164
A17: MAHKTECH | B17: 9 | C17: =ENTRY!B11 -> SILVERBEES | D17: =CAPITAL!$C$2 -> 3350000 | E17: =ENTRY!C11 -> 46038 | F17: =ENTRY!D11 -> 269.3 | G17: =ENTRY!E11 -> 259 | H17: =G17*ENTRY!$O11 -> 0 | I17: =G17*ENTRY!$P11 -> 0 | J17: =G17*ENTRY!$Q11 -> 259 | K17: =F17*G17 -> 69748.7 | L17: =ENTRY!F11 -> 280.95 | M17: =ENTRY!G11 -> 46041 | N17: =IFERROR(((L17-F17)*G17)/K17,"") -> 0.043260304 | O17: =IFERROR(N17*K17,"") -> 3017.35 | P17: =IFERROR((F17*H17)*N17,"") -> 0 | Q17: =IFERROR((F17*I17)*N17,"") -> 0 | R17: =IFERROR((F17*J17)*N17,"") -> 3017.35 | S17: =IFERROR(O17-Y17,"") -> 2859.02 | T17: =IFERROR(P17-Z17,"") -> 0 | U17: =IFERROR(Q17-AA17,"") -> 0 | V17: =IFERROR(R17-AB17,"") -> 2899.1933 | W17: =IFERROR(S17/K17,"") -> 0.040990298 | X17: =IFERROR(S17/D17,"") -> 0.00085343881 | Y17: =Brokerage(F17, L17, G17) -> 158.33 | Z17: =IF(H17=0,0,CAPITAL!$H$5*Y17) -> 0 | AA17: =IF(I17=0,0,CAPITAL!$H$6*Y17) -> 0 | AB17: =IF(J17=0,0,CAPITAL!$H$7*Y17) -> 118.15672
A18: HDFCGROWTH | B18: 10 | C18: =ENTRY!B12 -> SILVER LIFE (ADITYA BIRLA) | D18: =CAPITAL!$C$2 -> 3350000 | E18: =ENTRY!C12 -> 46041 | F18: =ENTRY!D12 -> 292.94 | G18: =ENTRY!E12 -> 238 | H18: =G18*ENTRY!$O12 -> 0 | I18: =G18*ENTRY!$P12 -> 0 | J18: =G18*ENTRY!$Q12 -> 238 | K18: =F18*G18 -> 69719.72 | L18: =ENTRY!F12 -> 311.85 | M18: =ENTRY!G12 -> 46042 | N18: =IFERROR(((L18-F18)*G18)/K18,"") -> 0.064552468 | O18: =IFERROR(N18*K18,"") -> 4500.58 | P18: =IFERROR((F18*H18)*N18,"") -> 0 | Q18: =IFERROR((F18*I18)*N18,"") -> 0 | R18: =IFERROR((F18*J18)*N18,"") -> 4500.58 | S18: =IFERROR(O18-Y18,"") -> 4341.2 | T18: =IFERROR(P18-Z18,"") -> 0 | U18: =IFERROR(Q18-AA18,"") -> 0 | V18: =IFERROR(R18-AB18,"") -> 4381.6397 | W18: =IFERROR(S18/K18,"") -> 0.062266458 | X18: =S18/D18 -> 0.0012958806 | Y18: =Brokerage(F18, L18, G18) -> 159.38 | Z18: =IF(H18=0,0,CAPITAL!$H$5*Y18) -> 0 | AA18: =IF(I18=0,0,CAPITAL!$H$6*Y18) -> 0 | AB18: =IF(J18=0,0,CAPITAL!$H$7*Y18) -> 118.9403
A19: LOWVOLIETF | B19: 11 | C19: =ENTRY!B13 -> TWCGOLD TEF | D19: =CAPITAL!$C$2 -> 3350000 | E19: =ENTRY!C13 -> 46042 | F19: =ENTRY!D13 -> 148.5 | G19: =ENTRY!E13 -> 473 | H19: =G19*ENTRY!$O13 -> 0 | I19: =G19*ENTRY!$P13 -> 0 | J19: =G19*ENTRY!$Q13 -> 473 | K19: =F19*G19 -> 70240.5 | L19: =ENTRY!F13 -> 158.07 | M19: =ENTRY!G13 -> 46043 | N19: =IFERROR(((L19-F19)*G19)/K19,"") -> 0.064444444 | O19: =IFERROR(N19*K19,"") -> 4526.61 | P19: =IFERROR((F19*H19)*N19,"") -> 0 | Q19: =IFERROR((F19*I19)*N19,"") -> 0 | R19: =IFERROR((F19*J19)*N19,"") -> 4526.61 | S19: =IFERROR(O19-Y19,"") -> 4365.18 | T19: =IFERROR(P19-Z19,"") -> 0 | U19: =IFERROR(Q19-AA19,"") -> 0 | V19: =IFERROR(R19-AB19,"") -> 4406.1399 | W19: =IFERROR(S19/K19,"") -> 0.062146198 | X19: =IFERROR(S19/D19,"") -> 0.0013030388 | Y19: =Brokerage(F19, L19, G19) -> 161.43 | Z19: =IF(H19=0,0,CAPITAL!$H$5*Y19) -> 0 | AA19: =IF(I19=0,0,CAPITAL!$H$6*Y19) -> 0 | AB19: =IF(J19=0,0,CAPITAL!$H$7*Y19) -> 120.47015
A20: HDFCQUAL | B20: 12 | C20: =ENTRY!B14 -> SILVERBAND (BANDHAN BANK) | D20: =CAPITAL!$C$2 -> 3350000 | E20: =ENTRY!C14 -> 46042 | F20: =ENTRY!D14 -> 326.44 | G20: =ENTRY!E14 -> 522 | H20: =G20*ENTRY!$O14 -> 0 | I20: =G20*ENTRY!$P14 -> 0 | J20: =G20*ENTRY!$Q14 -> 522 | K20: =F20*G20 -> 170401.68 | L20: =ENTRY!F14 -> LIVE | M20: =ENTRY!G14 | N20: =IFERROR(((L20-F20)*G20)/K20,"") | O20: =IFERROR(N20*K20,"") -> 0 | P20: =IFERROR((F20*H20)*N20,"") -> 0 | Q20: =IFERROR((F20*I20)*N20,"") -> 0 | R20: =IFERROR((F20*J20)*N20,"") -> 0 | S20: =IFERROR(O20-Y20,"") | T20: =IFERROR(P20-Z20,"") -> 0 | U20: =IFERROR(Q20-AA20,"") -> 0 | V20: =IFERROR(R20-AB20,"") | W20: =IFERROR(S20/K20,"") -> 0 | X20: =S20/D20 -> 0 | Y20: =Brokerage(F20, L20, G20) -> ERR | Z20: =IF(H20=0,0,CAPITAL!$H$5*Y20) -> 0 | AA20: =IF(I20=0,0,CAPITAL!$H$6*Y20) -> 0 | AB20: =IF(J20=0,0,CAPITAL!$H$7*Y20) -> #VALUE!
A21: BSE500IETF | B21: 13 | C21: =ENTRY!B15 -> SILVERBEES | D21: =CAPITAL!$C$2 -> 3350000 | E21: =ENTRY!C15 -> 46043 | F21: =ENTRY!D15 -> 304.57 | G21: =ENTRY!E15 -> 473 | H21: =G21*ENTRY!$O15 -> 0 | I21: =G21*ENTRY!$P15 -> 0 | J21: =G21*ENTRY!$Q15 -> 473 | K21: =F21*G21 -> 144061.61 | L21: =ENTRY!F15 -> 315.56 | M21: =ENTRY!G15 -> 46049 | N21: =IFERROR(((L21-F21)*G21)/K21,"") -> 0.036083659 | O21: =IFERROR(N21*K21,"") -> 5198.27 | P21: =IFERROR((F21*H21)*N21,"") -> 0 | Q21: =IFERROR((F21*I21)*N21,"") -> 0 | R21: =IFERROR((F21*J21)*N21,"") -> 5198.27 | S21: =IFERROR(O21-Y21,"") -> 4872.31 | T21: =IFERROR(P21-Z21,"") -> 0 | U21: =IFERROR(Q21-AA21,"") -> 0 | V21: =IFERROR(R21-AB21,"") -> 4955.0163 | W21: =IFERROR(S21/K21,"") -> 0.033821016 | X21: =IFERROR(S21/D21,"") -> 0.0014544209 | Y21: =Brokerage(F21, L21, G21) -> 325.96 | Z21: =IF(H21=0,0,CAPITAL!$H$5*Y21) -> 0 | AA21: =IF(I21=0,0,CAPITAL!$H$6*Y21) -> 0 | AB21: =IF(J21=0,0,CAPITAL!$H$7*Y21) -> 243.25373
A22: COMMOIETF | B22: 14 | C22: =ENTRY!B16 -> SILVERBAND (BANDHAN BANK) | D22: =CAPITAL!$C$2 -> 3350000 | E22: =ENTRY!C16 -> 46044 | F22: =ENTRY!D16 -> 295.2 | G22: =ENTRY!E16 -> 237 | H22: =G22*ENTRY!$O16 -> 0 | I22: =G22*ENTRY!$P16 -> 0 | J22: =G22*ENTRY!$Q16 -> 237 | K22: =F22*G22 -> 69962.4 | L22: =ENTRY!F16 -> LIVE | M22: =ENTRY!G16 | N22: =IFERROR(((L22-F22)*G22)/K22,"") | O22: =IFERROR(N22*K22,"") -> 0 | P22: =IFERROR((F22*H22)*N22,"") -> 0 | Q22: =IFERROR((F22*I22)*N22,"") -> 0 | R22: =IFERROR((F22*J22)*N22,"") -> 0 | S22: =IFERROR(O22-Y22,"") | T22: =IFERROR(P22-Z22,"") -> 0 | U22: =IFERROR(Q22-AA22,"") -> 0 | V22: =IFERROR(R22-AB22,"") | W22: =IFERROR(S22/K22,"") -> 0 | X22: =S22/D22 -> 0 | Y22: =Brokerage(F22, L22, G22) -> ERR | Z22: =IF(H22=0,0,CAPITAL!$H$5*Y22) -> 0 | AA22: =IF(I22=0,0,CAPITAL!$H$6*Y22) -> 0 | AB22: =IF(J22=0,0,CAPITAL!$H$7*Y22) -> #VALUE!
A23: FINIETF | B23: 15 | C23: =ENTRY!B17 -> SILVERBEES | D23: =CAPITAL!$C$2 -> 3350000 | E23: =ENTRY!C17 -> 46044 | F23: =ENTRY!D17 -> 271.82 | G23: =ENTRY!E17 -> 257 | H23: =G23*ENTRY!$O17 -> 0 | I23: =G23*ENTRY!$P17 -> 0 | J23: =G23*ENTRY!$Q17 -> 257 | K23: =F23*G23 -> 69857.74 | L23: =ENTRY!F17 -> 315.56 | M23: =ENTRY!G17 -> 46049 | N23: =IFERROR(((L23-F23)*G23)/K23,"") -> 0.16091531 | O23: =IFERROR(N23*K23,"") -> 11241.18 | P23: =IFERROR((F23*H23)*N23,"") -> 0 | Q23: =IFERROR((F23*I23)*N23,"") -> 0 | R23: =IFERROR((F23*J23)*N23,"") -> 11241.18 | S23: =IFERROR(O23-Y23,"") -> 11074.54 | T23: =IFERROR(P23-Z23,"") -> 0 | U23: =IFERROR(Q23-AA23,"") -> 0 | V23: =IFERROR(R23-AB23,"") -> 11116.822 | W23: =IFERROR(S23/K23,"") -> 0.15852989 | X23: =IFERROR(S23/D23,"") -> 0.0033058328 | Y23: =Brokerage(F23, L23, G23) -> 166.64 | Z23: =IF(H23=0,0,CAPITAL!$H$5*Y23) -> 0 | AA23: =IF(I23=0,0,CAPITAL!$H$6*Y23) -> 0 | AB23: =IF(J23=0,0,CAPITAL!$H$7*Y23) -> 124.35821
A24: INFRAIETF | B24: 16 | C24: =ENTRY!B18 -> SILVERBEES | D24: =CAPITAL!$C$2 -> 3350000 | E24: =ENTRY!C18 | F24: =ENTRY!D18 | G24: =ENTRY!E18 | H24: =G24*ENTRY!$O18 -> 0 | I24: =G24*ENTRY!$P18 -> 0 | J24: =G24*ENTRY!$Q18 -> 0 | K24: =F24*G24 -> 0 | L24: =ENTRY!F18 | M24: =ENTRY!G18 | N24: =IFERROR(((L24-F24)*G24)/K24,"") | O24: =IFERROR(N24*K24,"") -> 0 | P24: =IFERROR((F24*H24)*N24,"") -> 0 | Q24: =IFERROR((F24*I24)*N24,"") -> 0 | R24: =IFERROR((F24*J24)*N24,"") -> 0 | S24: =IFERROR(O24-Y24,"") | T24: =IFERROR(P24-Z24,"") -> 0 | U24: =IFERROR(Q24-AA24,"") -> 0 | V24: =IFERROR(R24-AB24,"") -> 0 | W24: =IFERROR(S24/K24,"") | X24: =S24/D24 -> 0 | Y24: =Brokerage(F24, L24, G24) -> ERR | Z24: =IF(H24=0,0,CAPITAL!$H$5*Y24) -> 0 | AA24: =IF(I24=0,0,CAPITAL!$H$6*Y24) -> 0 | AB24: =IF(J24=0,0,CAPITAL!$H$7*Y24) -> 0
A25: MNC | B25: 17 | C25: =ENTRY!B19 -> SILVERBEES | D25: =CAPITAL!$C$2 -> 3350000 | E25: =ENTRY!C19 | F25: =ENTRY!D19 | G25: =ENTRY!E19 | H25: =G25*ENTRY!$O19 -> 0 | I25: =G25*ENTRY!$P19 -> 0 | J25: =G25*ENTRY!$Q19 -> 0 | K25: =F25*G25 -> 0 | L25: =ENTRY!F19 | M25: =ENTRY!G19 | N25: =IFERROR(((L25-F25)*G25)/K25,"") | O25: =IFERROR(N25*K25,"") -> 0 | P25: =IFERROR((F25*H25)*N25,"") -> 0 | Q25: =IFERROR((F25*I25)*N25,"") -> 0 | R25: =IFERROR((F25*J25)*N25,"") -> 0 | S25: =IFERROR(O25-Y25,"") | T25: =IFERROR(P25-Z25,"") -> 0 | U25: =IFERROR(Q25-AA25,"") -> 0 | V25: =IFERROR(R25-AB25,"") -> 0 | W25: =IFERROR(S25/K25,"") | X25: =IFERROR(S25/D25,"") -> 0 | Y25: =Brokerage(F25, L25, G25) -> ERR | Z25: =IF(H25=0,0,CAPITAL!$H$5*Y25) -> 0 | AA25: =IF(I25=0,0,CAPITAL!$H$6*Y25) -> 0 | AB25: =IF(J25=0,0,CAPITAL!$H$7*Y25) -> 0
A26: ALPHAETF | B26: 17 | C26: =ENTRY!B20 -> SILVERBEES | D26: =CAPITAL!$C$2 -> 3350000 | E26: =ENTRY!C20 | F26: =ENTRY!D20 | G26: =ENTRY!E20 | H26: =G26*ENTRY!$O20 -> 0 | I26: =G26*ENTRY!$P20 -> 0 | J26: =G26*ENTRY!$Q20 -> 0 | K26: =F26*G26 -> 0 | L26: =ENTRY!F20 | M26: =ENTRY!G20 | N26: =IFERROR(((L26-F26)*G26)/K26,"") | O26: =IFERROR(N26*K26,"") -> 0 | P26: =IFERROR((F26*H26)*N26,"") -> 0 | Q26: =IFERROR((F26*I26)*N26,"") -> 0 | R26: =IFERROR((F26*J26)*N26,"") -> 0 | S26: =IFERROR(O26-Y26,"") | T26: =IFERROR(P26-Z26,"") -> 0 | U26: =IFERROR(Q26-AA26,"") -> 0 | V26: =IFERROR(R26-AB26,"") -> 0 | W26: =IFERROR(S26/K26,"") | X26: =S26/D26 -> 0 | Y26: =Brokerage(F26, L26, G26) -> ERR | Z26: =IF(H26=0,0,CAPITAL!$H$5*Y26) -> 0 | AA26: =IF(I26=0,0,CAPITAL!$H$6*Y26) -> 0 | AB26: =IF(J26=0,0,CAPITAL!$H$7*Y26) -> 0
A27: MIDSMALL | B27: 19 | C27: =ENTRY!B21 -> SILVERBEES | D27: =CAPITAL!$C$2 -> 3350000 | E27: =ENTRY!C21 | F27: =ENTRY!D21 | G27: =ENTRY!E21 | H27: =G27*ENTRY!$O21 -> 0 | I27: =G27*ENTRY!$P21 -> 0 | J27: =G27*ENTRY!$Q21 -> 0 | K27: =F27*G27 -> 0 | L27: =ENTRY!F21 | M27: =ENTRY!G21 | N27: =IFERROR(((L27-F27)*G27)/K27,"") | O27: =IFERROR(N27*K27,"") -> 0 | P27: =IFERROR((F27*H27)*N27,"") -> 0 | Q27: =IFERROR((F27*I27)*N27,"") -> 0 | R27: =IFERROR((F27*J27)*N27,"") -> 0 | S27: =IFERROR(O27-Y27,"") | T27: =IFERROR(P27-Z27,"") -> 0 | U27: =IFERROR(Q27-AA27,"") -> 0 | V27: =IFERROR(R27-AB27,"") -> 0 | W27: =IFERROR(S27/K27,"") | X27: =IFERROR(S27/D27,"") -> 0 | Y27: =Brokerage(F27, L27, G27) -> ERR | Z27: =IF(H27=0,0,CAPITAL!$H$5*Y27) -> 0 | AA27: =IF(I27=0,0,CAPITAL!$H$6*Y27) -> 0 | AB27: =IF(J27=0,0,CAPITAL!$H$7*Y27) -> 0
A28: SMALLCAP | B28: 20 | C28: =ENTRY!B22 -> SILVERBEES | D28: =CAPITAL!$C$2 -> 3350000 | E28: =ENTRY!C22 | F28: =ENTRY!D22 | G28: =ENTRY!E22 | H28: =G28*ENTRY!$O22 -> 0 | I28: =G28*ENTRY!$P22 -> 0 | J28: =G28*ENTRY!$Q22 -> 0 | K28: =F28*G28 -> 0 | L28: =ENTRY!F22 | M28: =ENTRY!G22 | N28: =IFERROR(((L28-F28)*G28)/K28,"") | O28: =IFERROR(N28*K28,"") -> 0 | P28: =IFERROR((F28*H28)*N28,"") -> 0 | Q28: =IFERROR((F28*I28)*N28,"") -> 0 | R28: =IFERROR((F28*J28)*N28,"") -> 0 | S28: =IFERROR(O28-Y28,"") | T28: =IFERROR(P28-Z28,"") -> 0 | U28: =IFERROR(Q28-AA28,"") -> 0 | V28: =IFERROR(R28-AB28,"") -> 0 | W28: =IFERROR(S28/K28,"") | X28: =S28/D28 -> 0 | Y28: =Brokerage(F28, L28, G28) -> ERR | Z28: =IF(H28=0,0,CAPITAL!$H$5*Y28) -> 0 | AA28: =IF(I28=0,0,CAPITAL!$H$6*Y28) -> 0 | AB28: =IF(J28=0,0,CAPITAL!$H$7*Y28) -> 0
A29: MONIFTY500 | B29: 21 | C29: =ENTRY!B23 -> SILVERBEES | D29: =CAPITAL!$C$2 -> 3350000 | E29: =ENTRY!C23 | F29: =ENTRY!D23 | G29: =ENTRY!E23 | H29: =G29*ENTRY!$O23 -> 0 | I29: =G29*ENTRY!$P23 -> 0 | J29: =G29*ENTRY!$Q23 -> 0 | K29: =F29*G29 -> 0 | L29: =ENTRY!F23 | M29: =ENTRY!G23 | N29: =IFERROR(((L29-F29)*G29)/K29,"") | O29: =IFERROR(N29*K29,"") -> 0 | P29: =IFERROR((F29*H29)*N29,"") -> 0 | Q29: =IFERROR((F29*I29)*N29,"") -> 0 | R29: =IFERROR((F29*J29)*N29,"") -> 0 | S29: =IFERROR(O29-Y29,"") | T29: =IFERROR(P29-Z29,"") -> 0 | U29: =IFERROR(Q29-AA29,"") -> 0 | V29: =IFERROR(R29-AB29,"") -> 0 | W29: =IFERROR(S29/K29,"") | X29: =IFERROR(S29/D29,"") -> 0 | Y29: =Brokerage(F29, L29, G29) -> ERR | Z29: =IF(H29=0,0,CAPITAL!$H$5*Y29) -> 0 | AA29: =IF(I29=0,0,CAPITAL!$H$6*Y29) -> 0 | AB29: =IF(J29=0,0,CAPITAL!$H$7*Y29) -> 0
A30: MOREALTY | B30: 22 | C30: =ENTRY!B24 -> SILVERBEES | D30: =CAPITAL!$C$2 -> 3350000 | E30: =ENTRY!C24 | F30: =ENTRY!D24 | G30: =ENTRY!E24 | H30: =G30*ENTRY!$O24 -> 0 | I30: =G30*ENTRY!$P24 -> 0 | J30: =G30*ENTRY!$Q24 -> 0 | K30: =F30*G30 -> 0 | L30: =ENTRY!F24 | M30: =ENTRY!G24 | N30: =IFERROR(((L30-F30)*G30)/K30,"") | O30: =IFERROR(N30*K30,"") -> 0 | P30: =IFERROR((F30*H30)*N30,"") -> 0 | Q30: =IFERROR((F30*I30)*N30,"") -> 0 | R30: =IFERROR((F30*J30)*N30,"") -> 0 | S30: =IFERROR(O30-Y30,"") | T30: =IFERROR(P30-Z30,"") -> 0 | U30: =IFERROR(Q30-AA30,"") -> 0 | V30: =IFERROR(R30-AB30,"") -> 0 | W30: =IFERROR(S30/K30,"") | X30: =S30/D30 -> 0 | Y30: =Brokerage(F30, L30, G30) -> ERR | Z30: =IF(H30=0,0,CAPITAL!$H$5*Y30) -> 0 | AA30: =IF(I30=0,0,CAPITAL!$H$6*Y30) -> 0 | AB30: =IF(J30=0,0,CAPITAL!$H$7*Y30) -> 0
A31: MOSMALL250 | B31: 23 | C31: =ENTRY!B25 -> SILVERBEES | D31: =CAPITAL!$C$2 -> 3350000 | E31: =ENTRY!C25 | F31: =ENTRY!D25 | G31: =ENTRY!E25 | H31: =G31*ENTRY!$O25 -> 0 | I31: =G31*ENTRY!$P25 -> 0 | J31: =G31*ENTRY!$Q25 -> 0 | K31: =F31*G31 -> 0 | L31: =ENTRY!F25 | M31: =ENTRY!G25 | N31: =IFERROR(((L31-F31)*G31)/K31,"") | O31: =IFERROR(N31*K31,"") -> 0 | P31: =IFERROR((F31*H31)*N31,"") -> 0 | Q31: =IFERROR((F31*I31)*N31,"") -> 0 | R31: =IFERROR((F31*J31)*N31,"") -> 0 | S31: =IFERROR(O31-Y31,"") | T31: =IFERROR(P31-Z31,"") -> 0 | U31: =IFERROR(Q31-AA31,"") -> 0 | V31: =IFERROR(R31-AB31,"") -> 0 | W31: =IFERROR(S31/K31,"") | X31: =IFERROR(S31/D31,"") -> 0 | Y31: =Brokerage(F31, L31, G31) -> ERR | Z31: =IF(H31=0,0,CAPITAL!$H$5*Y31) -> 0 | AA31: =IF(I31=0,0,CAPITAL!$H$6*Y31) -> 0 | AB31: =IF(J31=0,0,CAPITAL!$H$7*Y31) -> 0
A32: MOVALUE | B32: 24 | C32: =ENTRY!B26 -> SILVERBEES | D32: =CAPITAL!$C$2 -> 3350000 | E32: =ENTRY!C26 | F32: =ENTRY!D26 | G32: =ENTRY!E26 | H32: =G32*ENTRY!$O26 -> 0 | I32: =G32*ENTRY!$P26 -> 0 | J32: =G32*ENTRY!$Q26 -> 0 | K32: =F32*G32 -> 0 | L32: =ENTRY!F26 | M32: =ENTRY!G26 | N32: =IFERROR(((L32-F32)*G32)/K32,"") | O32: =IFERROR(N32*K32,"") -> 0 | P32: =IFERROR((F32*H32)*N32,"") -> 0 | Q32: =IFERROR((F32*I32)*N32,"") -> 0 | R32: =IFERROR((F32*J32)*N32,"") -> 0 | S32: =IFERROR(O32-Y32,"") | T32: =IFERROR(P32-Z32,"") -> 0 | U32: =IFERROR(Q32-AA32,"") -> 0 | V32: =IFERROR(R32-AB32,"") -> 0 | W32: =IFERROR(S32/K32,"") | X32: =S32/D32 -> 0 | Y32: =Brokerage(F32, L32, G32) -> ERR | Z32: =IF(H32=0,0,CAPITAL!$H$5*Y32) -> 0 | AA32: =IF(I32=0,0,CAPITAL!$H$6*Y32) -> 0 | AB32: =IF(J32=0,0,CAPITAL!$H$7*Y32) -> 0
A33: MONQ50 | B33: 25 | C33: =ENTRY!B27 -> SILVERBEES | D33: =CAPITAL!$C$2 -> 3350000 | E33: =ENTRY!C27 | F33: =ENTRY!D27 | G33: =ENTRY!E27 | H33: =G33*ENTRY!$O27 -> 0 | I33: =G33*ENTRY!$P27 -> 0 | J33: =G33*ENTRY!$Q27 -> 0 | K33: =F33*G33 -> 0 | L33: =ENTRY!F27 | M33: =ENTRY!G27 | N33: =IFERROR(((L33-F33)*G33)/K33,"") | O33: =IFERROR(N33*K33,"") -> 0 | P33: =IFERROR((F33*H33)*N33,"") -> 0 | Q33: =IFERROR((F33*I33)*N33,"") -> 0 | R33: =IFERROR((F33*J33)*N33,"") -> 0 | S33: =IFERROR(O33-Y33,"") | T33: =IFERROR(P33-Z33,"") -> 0 | U33: =IFERROR(Q33-AA33,"") -> 0 | V33: =IFERROR(R33-AB33,"") -> 0 | W33: =IFERROR(S33/K33,"") | X33: =IFERROR(S33/D33,"") -> 0 | Y33: =Brokerage(F33, L33, G33) -> ERR | Z33: =IF(H33=0,0,CAPITAL!$H$5*Y33) -> 0 | AA33: =IF(I33=0,0,CAPITAL!$H$6*Y33) -> 0 | AB33: =IF(J33=0,0,CAPITAL!$H$7*Y33) -> 0
A34: MON100 | B34: 26 | C34: =ENTRY!B28 -> SILVERBEES | D34: =CAPITAL!$C$2 -> 3350000 | E34: =ENTRY!C28 | F34: =ENTRY!D28 | G34: =ENTRY!E28 | H34: =G34*ENTRY!$O28 -> 0 | I34: =G34*ENTRY!$P28 -> 0 | J34: =G34*ENTRY!$Q28 -> 0 | K34: =F34*G34 -> 0 | L34: =ENTRY!F28 | M34: =ENTRY!G28 | N34: =IFERROR(((L34-F34)*G34)/K34,"") | O34: =IFERROR(N34*K34,"") -> 0 | P34: =IFERROR((F34*H34)*N34,"") -> 0 | Q34: =IFERROR((F34*I34)*N34,"") -> 0 | R34: =IFERROR((F34*J34)*N34,"") -> 0 | S34: =IFERROR(O34-Y34,"") | T34: =IFERROR(P34-Z34,"") -> 0 | U34: =IFERROR(Q34-AA34,"") -> 0 | V34: =IFERROR(R34-AB34,"") -> 0 | W34: =IFERROR(S34/K34,"") | X34: =S34/D34 -> 0 | Y34: =Brokerage(F34, L34, G34) -> ERR | Z34: =IF(H34=0,0,CAPITAL!$H$5*Y34) -> 0 | AA34: =IF(I34=0,0,CAPITAL!$H$6*Y34) -> 0 | AB34: =IF(J34=0,0,CAPITAL!$H$7*Y34) -> 0
A35: TOP100CASE | B35: 27 | C35: =ENTRY!B29 -> SILVERBEES | D35: =CAPITAL!$C$2 -> 3350000 | E35: =ENTRY!C29 | F35: =ENTRY!D29 | G35: =ENTRY!E29 | H35: =G35*ENTRY!$O29 -> 0 | I35: =G35*ENTRY!$P29 -> 0 | J35: =G35*ENTRY!$Q29 -> 0 | K35: =F35*G35 -> 0 | L35: =ENTRY!F29 | M35: =ENTRY!G29 | N35: =IFERROR(((L35-F35)*G35)/K35,"") | O35: =IFERROR(N35*K35,"") -> 0 | P35: =IFERROR((F35*H35)*N35,"") -> 0 | Q35: =IFERROR((F35*I35)*N35,"") -> 0 | R35: =IFERROR((F35*J35)*N35,"") -> 0 | S35: =IFERROR(O35-Y35,"") | T35: =IFERROR(P35-Z35,"") -> 0 | U35: =IFERROR(Q35-AA35,"") -> 0 | V35: =IFERROR(R35-AB35,"") -> 0 | W35: =IFERROR(S35/K35,"") | X35: =IFERROR(S35/D35,"") -> 0 | Y35: =Brokerage(F35, L35, G35) -> ERR | Z35: =IF(H35=0,0,CAPITAL!$H$5*Y35) -> 0 | AA35: =IF(I35=0,0,CAPITAL!$H$6*Y35) -> 0 | AB35: =IF(J35=0,0,CAPITAL!$H$7*Y35) -> 0
A36: NIFTYBEES | B36: 28 | C36: =ENTRY!B30 -> SILVERBEES | D36: =CAPITAL!$C$2 -> 3350000 | E36: =ENTRY!C30 | F36: =ENTRY!D30 | G36: =ENTRY!E30 | H36: =G36*ENTRY!$O30 -> 0 | I36: =G36*ENTRY!$P30 -> 0 | J36: =G36*ENTRY!$Q30 -> 0 | K36: =F36*G36 -> 0 | L36: =ENTRY!F30 | M36: =ENTRY!G30 | N36: =IFERROR(((L36-F36)*G36)/K36,"") | O36: =IFERROR(N36*K36,"") -> 0 | P36: =IFERROR((F36*H36)*N36,"") -> 0 | Q36: =IFERROR((F36*I36)*N36,"") -> 0 | R36: =IFERROR((F36*J36)*N36,"") -> 0 | S36: =IFERROR(O36-Y36,"") | T36: =IFERROR(P36-Z36,"") -> 0 | U36: =IFERROR(Q36-AA36,"") -> 0 | V36: =IFERROR(R36-AB36,"") -> 0 | W36: =IFERROR(S36/K36,"") | X36: =S36/D36 -> 0 | Y36: =Brokerage(F36, L36, G36) -> ERR | Z36: =IF(H36=0,0,CAPITAL!$H$5*Y36) -> 0 | AA36: =IF(I36=0,0,CAPITAL!$H$6*Y36) -> 0 | AB36: =IF(J36=0,0,CAPITAL!$H$7*Y36) -> 0
A37: MOMENTUM50 | B37: 29 | C37: =ENTRY!B31 -> SILVERBEES | D37: =CAPITAL!$C$2 -> 3350000 | E37: =ENTRY!C31 | F37: =ENTRY!D31 | G37: =ENTRY!E31 | H37: =G37*ENTRY!$O31 -> 0 | I37: =G37*ENTRY!$P31 -> 0 | J37: =G37*ENTRY!$Q31 -> 0 | K37: =F37*G37 -> 0 | L37: =ENTRY!F31 | M37: =ENTRY!G31 | N37: =IFERROR(((L37-F37)*G37)/K37,"") | O37: =IFERROR(N37*K37,"") -> 0 | P37: =IFERROR((F37*H37)*N37,"") -> 0 | Q37: =IFERROR((F37*I37)*N37,"") -> 0 | R37: =IFERROR((F37*J37)*N37,"") -> 0 | S37: =IFERROR(O37-Y37,"") | T37: =IFERROR(P37-Z37,"") -> 0 | U37: =IFERROR(Q37-AA37,"") -> 0 | V37: =IFERROR(R37-AB37,"") -> 0 | W37: =IFERROR(S37/K37,"") | X37: =IFERROR(S37/D37,"") -> 0 | Y37: =Brokerage(F37, L37, G37) -> ERR | Z37: =IF(H37=0,0,CAPITAL!$H$5*Y37) -> 0 | AA37: =IF(I37=0,0,CAPITAL!$H$6*Y37) -> 0 | AB37: =IF(J37=0,0,CAPITAL!$H$7*Y37) -> 0
A38: ALPHA | B38: 30 | C38: =ENTRY!B32 -> SILVERBEES | D38: =CAPITAL!$C$2 -> 3350000 | E38: =ENTRY!C32 | F38: =ENTRY!D32 | G38: =ENTRY!E32 | H38: =G38*ENTRY!$O32 -> 0 | I38: =G38*ENTRY!$P32 -> 0 | J38: =G38*ENTRY!$Q32 -> 0 | K38: =F38*G38 -> 0 | L38: =ENTRY!F32 | M38: =ENTRY!G32 | N38: =IFERROR(((L38-F38)*G38)/K38,"") | O38: =IFERROR(N38*K38,"") -> 0 | P38: =IFERROR((F38*H38)*N38,"") -> 0 | Q38: =IFERROR((F38*I38)*N38,"") -> 0 | R38: =IFERROR((F38*J38)*N38,"") -> 0 | S38: =IFERROR(O38-Y38,"") | T38: =IFERROR(P38-Z38,"") -> 0 | U38: =IFERROR(Q38-AA38,"") -> 0 | V38: =IFERROR(R38-AB38,"") -> 0 | W38: =IFERROR(S38/K38,"") | X38: =S38/D38 -> 0 | Y38: =Brokerage(F38, L38, G38) -> ERR | Z38: =IF(H38=0,0,CAPITAL!$H$5*Y38) -> 0 | AA38: =IF(I38=0,0,CAPITAL!$H$6*Y38) -> 0 | AB38: =IF(J38=0,0,CAPITAL!$H$7*Y38) -> 0
A39: ALPL30IETF | B39: 31 | C39: =ENTRY!B33 -> SILVERBEES | D39: =CAPITAL!$C$2 -> 3350000 | E39: =ENTRY!C33 | F39: =ENTRY!D33 | G39: =ENTRY!E33 | H39: =G39*ENTRY!$O33 -> 0 | I39: =G39*ENTRY!$P33 -> 0 | J39: =G39*ENTRY!$Q33 -> 0 | K39: =F39*G39 -> 0 | L39: =ENTRY!F33 | M39: =ENTRY!G33 | N39: =IFERROR(((L39-F39)*G39)/K39,"") | O39: =IFERROR(N39*K39,"") -> 0 | P39: =IFERROR((F39*H39)*N39,"") -> 0 | Q39: =IFERROR((F39*I39)*N39,"") -> 0 | R39: =IFERROR((F39*J39)*N39,"") -> 0 | S39: =IFERROR(O39-Y39,"") | T39: =IFERROR(P39-Z39,"") -> 0 | U39: =IFERROR(Q39-AA39,"") -> 0 | V39: =IFERROR(R39-AB39,"") -> 0 | W39: =IFERROR(S39/K39,"") | X39: =IFERROR(S39/D39,"") -> 0 | Y39: =Brokerage(F39, L39, G39) -> ERR | Z39: =IF(H39=0,0,CAPITAL!$H$5*Y39) -> 0 | AA39: =IF(I39=0,0,CAPITAL!$H$6*Y39) -> 0 | AB39: =IF(J39=0,0,CAPITAL!$H$7*Y39) -> 0
A40: AUTOIETF | B40: 32 | C40: =ENTRY!B34 -> SILVERBEES | D40: =CAPITAL!$C$2 -> 3350000 | E40: =ENTRY!C34 | F40: =ENTRY!D34 | G40: =ENTRY!E34 | H40: =G40*ENTRY!$O34 -> 0 | I40: =G40*ENTRY!$P34 -> 0 | J40: =G40*ENTRY!$Q34 -> 0 | K40: =F40*G40 -> 0 | L40: =ENTRY!F34 | M40: =ENTRY!G34 | N40: =IFERROR(((L40-F40)*G40)/K40,"") | O40: =IFERROR(N40*K40,"") -> 0 | P40: =IFERROR((F40*H40)*N40,"") -> 0 | Q40: =IFERROR((F40*I40)*N40,"") -> 0 | R40: =IFERROR((F40*J40)*N40,"") -> 0 | S40: =IFERROR(O40-Y40,"") | T40: =IFERROR(P40-Z40,"") -> 0 | U40: =IFERROR(Q40-AA40,"") -> 0 | V40: =IFERROR(R40-AB40,"") -> 0 | W40: =IFERROR(S40/K40,"") | X40: =S40/D40 -> 0 | Y40: =Brokerage(F40, L40, G40) -> ERR | Z40: =IF(H40=0,0,CAPITAL!$H$5*Y40) -> 0 | AA40: =IF(I40=0,0,CAPITAL!$H$6*Y40) -> 0 | AB40: =IF(J40=0,0,CAPITAL!$H$7*Y40) -> 0
A41: BANKBEES | B41: 33 | C41: =ENTRY!B35 -> SILVERBEES | D41: =CAPITAL!$C$2 -> 3350000 | E41: =ENTRY!C35 | F41: =ENTRY!D35 | G41: =ENTRY!E35 | H41: =G41*ENTRY!$O35 -> 0 | I41: =G41*ENTRY!$P35 -> 0 | J41: =G41*ENTRY!$Q35 -> 0 | K41: =F41*G41 -> 0 | L41: =ENTRY!F35 | M41: =ENTRY!G35 | N41: =IFERROR(((L41-F41)*G41)/K41,"") | O41: =IFERROR(N41*K41,"") -> 0 | P41: =IFERROR((F41*H41)*N41,"") -> 0 | Q41: =IFERROR((F41*I41)*N41,"") -> 0 | R41: =IFERROR((F41*J41)*N41,"") -> 0 | S41: =IFERROR(O41-Y41,"") | T41: =IFERROR(P41-Z41,"") -> 0 | U41: =IFERROR(Q41-AA41,"") -> 0 | V41: =IFERROR(R41-AB41,"") -> 0 | W41: =IFERROR(S41/K41,"") | X41: =IFERROR(S41/D41,"") -> 0 | Y41: =Brokerage(F41, L41, G41) -> ERR | Z41: =IF(H41=0,0,CAPITAL!$H$5*Y41) -> 0 | AA41: =IF(I41=0,0,CAPITAL!$H$6*Y41) -> 0 | AB41: =IF(J41=0,0,CAPITAL!$H$7*Y41) -> 0
A42: DIVOPPBEES | B42: 34 | C42: =ENTRY!B36 -> SILVERBEES | D42: =CAPITAL!$C$2 -> 3350000 | E42: =ENTRY!C36 | F42: =ENTRY!D36 | G42: =ENTRY!E36 | H42: =G42*ENTRY!$O36 -> 0 | I42: =G42*ENTRY!$P36 -> 0 | J42: =G42*ENTRY!$Q36 -> 0 | K42: =F42*G42 -> 0 | L42: =ENTRY!F36 | M42: =ENTRY!G36 | N42: =IFERROR(((L42-F42)*G42)/K42,"") | O42: =IFERROR(N42*K42,"") -> 0 | P42: =IFERROR((F42*H42)*N42,"") -> 0 | Q42: =IFERROR((F42*I42)*N42,"") -> 0 | R42: =IFERROR((F42*J42)*N42,"") -> 0 | S42: =IFERROR(O42-Y42,"") | T42: =IFERROR(P42-Z42,"") -> 0 | U42: =IFERROR(Q42-AA42,"") -> 0 | V42: =IFERROR(R42-AB42,"") -> 0 | W42: =IFERROR(S42/K42,"") | X42: =S42/D42 -> 0 | Y42: =Brokerage(F42, L42, G42) -> ERR | Z42: =IF(H42=0,0,CAPITAL!$H$5*Y42) -> 0 | AA42: =IF(I42=0,0,CAPITAL!$H$6*Y42) -> 0 | AB42: =IF(J42=0,0,CAPITAL!$H$7*Y42) -> 0
...

Sheet SA_PROFIT_SHARING
A2: Total Gain on GIVEN Capital → | E2: =IFERROR(__xludf.DUMMYFUNCTION("SUM( FILTER(JOURNAL!X9:X1015, ISNUMBER(JOURNAL!X9:X1015)) )"),0.015051871641791037) -> 0.015051872 | F2: =JOURNAL!T6 -> 633.45943
A4: Availabe for Withdraw | D4: =F2-(SUM(D9:D62)) -> 628.45943 | E4: =SUM(E9:E62) -> 4.5 | F4: =SUM(F9:F62) -> 0.5
A6: NO. | B6: CAPITAL | C6: DATE | D6: AMOUNT | E6: SUJAY | F6: DENISH | G6: SHARING STATUS
E7: 0.9 | F7: 0.1
A9: 1 | B9: =CAPITAL!$C$5 -> 150000 | C9: 45986 | D9: 5 | E9: =D9*$E$7 -> 4.5 | F9: =D9*$F$7 -> 0.5 | G9: DONE
A10: 2 | B10: =CAPITAL!$C$5 -> 150000 | E10: =D10*$E$7 -> 0 | F10: =D10*$F$7 -> 0
A11: 3 | B11: =CAPITAL!$C$5 -> 150000 | E11: =D11*$E$7 -> 0 | F11: =D11*$F$7 -> 0
A12: 4 | B12: =CAPITAL!$C$5 -> 150000 | E12: =D12*$E$7 -> 0 | F12: =D12*$F$7 -> 0
A13: 5 | B13: =CAPITAL!$C$5 -> 150000 | E13: =D13*$E$7 -> 0 | F13: =D13*$F$7 -> 0
A14: 6 | B14: =CAPITAL!$C$5 -> 150000 | E14: =D14*$E$7 -> 0 | F14: =D14*$F$7 -> 0
A15: 7 | B15: =CAPITAL!$C$5 -> 150000 | E15: =D15*$E$7 -> 0 | F15: =D15*$F$7 -> 0
A16: 8 | B16: =CAPITAL!$C$5 -> 150000 | E16: =D16*$E$7 -> 0 | F16: =D16*$F$7 -> 0
A17: 9 | B17: =CAPITAL!$C$5 -> 150000 | E17: =D17*$E$7 -> 0 | F17: =D17*$F$7 -> 0
A18: 10 | B18: =CAPITAL!$C$5 -> 150000 | E18: =D18*$E$7 -> 0 | F18: =D18*$F$7 -> 0
A19: 11 | B19: =CAPITAL!$C$5 -> 150000 | E19: =D19*$E$7 -> 0 | F19: =D19*$F$7 -> 0
A20: 12 | B20: =CAPITAL!$C$5 -> 150000 | E20: =D20*$E$7 -> 0 | F20: =D20*$F$7 -> 0
A21: 13 | B21: =CAPITAL!$C$5 -> 150000 | E21: =D21*$E$7 -> 0 | F21: =D21*$F$7 -> 0
... A63: 55 | B63: =CAPITAL!$C$5 -> 150000 | E63: =D63*$E$7 -> 0 | F63: =D63*$F$7 -> 0

Sheet SG_PROFIT_SHARING
E1: 2025 Profit
A2: Total Gain on GIVEN Capital → | E2: =IFERROR(__xludf.DUMMYFUNCTION("SUM( FILTER(JOURNAL!X9:X1015, ISNUMBER(JOURNAL!X9:X1015)) )"),0.015051871641791037) -> 0.015051872 | F2: =JOURNAL!U6+F1 -> 2520.9252
A4: Availabe for Withdraw | D4: =F2-(SUM(D9:D62)) -> 2520.9252 | E4: =SUM(E9:E62) -> 0 | F4: =SUM(F9:F62) -> 0
A6: NO. | B6: CAPITAL | C6: DATE | D6: AMOUNT | E6: SG | F6: DENISH | G6: SHARING STATUS
E7: 0.9 | F7: 0.1
A9: 1 | B9: =CAPITAL!$C$6 -> 700000 | C9: 45986 | E9: =D9*$E$7 -> 0 | F9: =D9*$F$7 -> 0 | G9: DONE
A10: 2 | B10: =CAPITAL!$C$6 -> 700000 | E10: =D10*$E$7 -> 0 | F10: =D10*$F$7 -> 0
A11: 3 | B11: =CAPITAL!$C$6 -> 700000 | E11: =D11*$E$7 -> 0 | F11: =D11*$F$7 -> 0
A12: 4 | B12: =CAPITAL!$C$6 -> 700000 | E12: =D12*$E$7 -> 0 | F12: =D12*$F$7 -> 0
A13: 5 | B13: =CAPITAL!$C$6 -> 700000 | E13: =D13*$E$7 -> 0 | F13: =D13*$F$7 -> 0
A14: 6 | B14: =CAPITAL!$C$6 -> 700000 | E14: =D14*$E$7 -> 0 | F14: =D14*$F$7 -> 0
A15: 7 | B15: =CAPITAL!$C$6 -> 700000 | E15: =D15*$E$7 -> 0 | F15: =D15*$F$7 -> 0
A16: 8 | B16: =CAPITAL!$C$6 -> 700000 | E16: =D16*$E$7 -> 0 | F16: =D16*$F$7 -> 0
A17: 9 | B17: =CAPITAL!$C$6 -> 700000 | E17: =D17*$E$7 -> 0 | F17: =D17*$F$7 -> 0
A18: 10 | B18: =CAPITAL!$C$6 -> 700000 | E18: =D18*$E$7 -> 0 | F18: =D18*$F$7 -> 0
A19: 11 | B19: =CAPITAL!$C$6 -> 700000 | E19: =D19*$E$7 -> 0 | F19: =D19*$F$7 -> 0
A20: 12 | B20: =CAPITAL!$C$6 -> 700000 | E20: =D20*$E$7 -> 0 | F20: =D20*$F$7 -> 0
A21: 13 | B21: =CAPITAL!$C$6 -> 700000 | E21: =D21*$E$7 -> 0 | F21: =D21*$F$7 -> 0
... A63: 55 | B63: =CAPITAL!$C$6 -> 700000 | E63: =D63*$E$7 -> 0 | F63: =D63*$F$7 -> 0

Sheet TXN
A1: SA - FUND GIVEN | E1: SG - FUND GIVEN
A3: NO. | B3: DATE | C3: AMOUNT | E3: NO. | F3: DATE | G3: AMOUNT
B5: SUM | C5: =SUM(C7:C56) -> 150000 | F5: SUM | G5: =SUM(G7:G56) -> 700000
A7: 1 | B7: 45782 | C7: 50000 | E7: 1 | F7: 45789 | G7: 200000
A8: 2 | B8: 45798 | C8: 40000 | E8: 2 | F8: 45834 | G8: 200000
A9: 3 | B9: 45832 | C9: 60000 | E9: 3 | F9: 45874 | G9: 100000
A10: 4 | E10: 4 | F10: 45979 | G10: 200000
A11: 5 | E11: 5
A12: 6 | E12: 6
E13: 7
E14: 8
E15: 9
E16: 10
E17: 11
E18: 12
E19: 13
E20: 14
E21: 15
E22: 16

Sheet Brokerage
B4: Before Brokrage | C4: TOTAL PROFIT | E4: BUY | F4: SELL | G4: QNT | H4: Profit | I4: Net Profit
B5: Total Brokrage | E5: =SA_JOURNAL!F9 -> #REF! | F5: =SA_JOURNAL!I9 -> #REF! | G5: =SA_JOURNAL!G9 -> #REF! | H5: =(F5-E5)*G5 -> #REF! | I5: =H5-E16 -> #REF!
D6: VALUE | E6: =E5*G5 -> #REF! | F6: =F5*G5 -> #REF! | G6: =E6+F6 -> #REF!
B8: Net Release | E8: =E6*0.001 -> #REF!
C9: STT/CTT | D9: 0.001 | E9: =E6*D9 -> #REF! | F9: =F6*D9 -> #REF! | G9: =E9+F9 -> #REF!
C10: TRANSACTION | D10: 3e-05 | E10: =D10*G6 -> #REF! | H10: 0.6
C11: SEBI | D11: 1e-06 | E11: =G6*D11 -> #REF! | H11: 0.02
D12: Transaction + SEBI | E12: =E10+E11 -> #REF!
C13: GST ON TRANSACTION AND SEBI CHARGES | D13: 0.18 | E13: =E12*D13 -> #REF! | K13: 0.0001/100
C14: STAMP DUTY (Buy Only) | D14: 0.00015 | E14: =D14*E6 -> #REF! | H14: 1.5 | K14: =0.001/100 -> 1e-05
E16: =G9+E10+E11+E13+E14 -> #REF!
